Workbook

Sheet Read me
A1: Leap Auto Parts: master parts catalog (version 2: one-word categories)
A3: What this is
A4: A complete list of the parts of a car in the column order of your Categories sheet (English block, Arabic block, Chinese block) with the English WEIGHT column added. It covers combustion, hybrid, range-extender and electric cars. Counts are on 'Categories' and 'Checks'.
A6: The naming rules (checked automatically on the 'Checks' sheet)
A7: Main category: ONE word. Sub-category: 1 to 3 words. Part name: 1 to 5 words, always starting with its sub-category: the sub-category plus a position (Brake Pad Set - Front) or, for fluids and chemicals, plus a pack size (Engine Oil 4 L).
A8: Bracket text is never part of a name: an alias such as (DPF) or (Sway Bar) is in the Search Keywords columns (English, Arabic, Chinese), together with the longer original name where a name was shortened.
A10: The sheets
A11: Catalog: one row per part name (the format you asked for). Length, width, height, weight, applies-to, shipping notes and keywords are looked up from 'Part types'; the Arabic and Chinese measurement columns copy the English ones.
A12: Part types: the MASTER list, one row per part (a pack size is a separate row, with its own size). The sheet to edit, and the one a category import for the marketplace would read.
A13: Categories, Positions, Placements, Size scale: the lists the catalog uses, with live counts. Checks: automatic tests (all should say PASS).
A15: Where to edit (legend)
A16: Change a size or weight: 'Part types', columns Length, Width, Height, Weight. Change it ONCE; the Catalog follows. Then change 'Size Basis' to "Measured".
... A35: 8. Not covered yet: motorcycles, trucks and buses, agricultural vehicles, brand-specific parts.

Sheet Catalog
A1: SKU / الرمز / SKU | B1: Main Category | C1: Sub Category | D1: Part Name | E1: Position | F1: Placement | G1: Length (cm) | H1: Width (cm) | I1: Height (cm) | J1: Weight (kg) | K1: التصنيف الرئيسي | L1: التصنيف الفرعي | M1: اسم القطعة | N1: الجهة | O1: مكان التركيب | P1: الطول (سم) | Q1: العرض (سم) | R1: الارتفاع (سم) | S1: الوزن (كجم) | T1: 主类别 | U1: 子类别 | V1: 零件名称 | W1: 位置 | X1: 安装位置 | Y1: 长度 (厘米) | Z1: 宽度 (厘米) | AA1: 高度 (厘米) | AB1: 重量 (公斤) | AC1: Main Category Code | AD1: Sub Category Code | AE1: Applies To | AF1: Special Shipping | AG1: Size Basis | AH1: Search Keywords (English) | AI1: Search Keywords (Arabic) | AJ1: Search Keywords (Chinese) | AK1: Master Row (helper)
A2: SKU1000 | B2: Engine | C2: Engine Assembly | D2: =C2&" - "&E2 -> Engine Assembly - Universal | E2: Universal | F2: Engine Bay | G2: =IF($AK2=0,"",INDEX('Part types'!$P:$P,$AK2)) -> 110 | H2: =IF($AK2=0,"",INDEX('Part types'!$Q:$Q,$AK2)) -> 75 | I2: =IF($AK2=0,"",INDEX('Part types'!$R:$R,$AK2)) -> 75 | J2: =IF($AK2=0,"",INDEX('Part types'!$S:$S,$AK2)) -> 150 | K2: المحرك | L2: محرك كامل | M2: =L2&" - "&N2 -> محرك كامل - عام | N2: عام | O2: حجرة المحرك | P2: =G2 -> 110 | Q2: =H2 -> 75 | R2: =I2 -> 75 | S2: =J2 -> 150 | T2: 发动机 | U2: 发动机总成 | V2: =U2&" - "&W2 -> 发动机总成 - 通用 | W2: 通用 | X2: 发动机舱 | Y2: =G2 -> 110 | Z2: =H2 -> 75 | AA2: =I2 -> 75 | AB2: =J2 -> 150 | AC2: ENG | AD2: ENG-001 | AE2: =IF($AK2=0,"",INDEX('Part types'!$T:$T,$AK2)&"") -> Combustion engine (petrol, diesel, hybrid, range extender) | AF2: =IF($AK2=0,"",INDEX('Part types'!$U:$U,$AK2)&"") -> Heavy (over 30 kg) | AG2: =IF($AK2=0,"",INDEX('Part types'!$V:$V,$AK2)&"") -> Estimate: item-specific | AH2: =IF($AK2=0,"",INDEX('Part types'!$W:$W,$AK2)&"") -> Complete | AI2: =IF($AK2=0,"",INDEX('Part types'!$X:$X,$AK2)&"") | AJ2: =IF($AK2=0,"",INDEX('Part types'!$Y:$Y,$AK2)&"") | AK2: =IFERROR(MATCH($AD2,'Part types'!$E:$E,0),0) -> 2
A3: SKU1001 | B3: Engine | C3: Short Block | D3: =C3&" - "&E3 -> Short Block - Universal | E3: Universal | F3: Engine Bay | G3: =IF($AK3=0,"",INDEX('Part types'!$P:$P,$AK3)) -> 80 | H3: =IF($AK3=0,"",INDEX('Part types'!$Q:$Q,$AK3)) -> 60 | I3: =IF($AK3=0,"",INDEX('Part types'!$R:$R,$AK3)) -> 60 | J3: =IF($AK3=0,"",INDEX('Part types'!$S:$S,$AK3)) -> 80 | K3: المحرك | L3: هيكل المحرك | M3: =L3&" - "&N3 -> هيكل المحرك - عام | N3: عام | O3: حجرة المحرك | P3: =G3 -> 80 | Q3: =H3 -> 60 | R3: =I3 -> 60 | S3: =J3 -> 80 | T3: 发动机 | U3: 发动机短缸体总成 | V3: =U3&" - "&W3 -> 发动机短缸体总成 - 通用 | W3: 通用 | X3: 发动机舱 | Y3: =G3 -> 80 | Z3: =H3 -> 60 | AA3: =I3 -> 60 | AB3: =J3 -> 80 | AC3: ENG | AD3: ENG-002 | AE3: =IF($AK3=0,"",INDEX('Part types'!$T:$T,$AK3)&"") -> Combustion engine (petrol, diesel, hybrid, range extender) | AF3: =IF($AK3=0,"",INDEX('Part types'!$U:$U,$AK3)&"") -> Heavy (over 30 kg) | AG3: =IF($AK3=0,"",INDEX('Part types'!$V:$V,$AK3)&"") -> Estimate: item-specific | AH3: =IF($AK3=0,"",INDEX('Part types'!$W:$W,$AK3)&"") | AI3: =IF($AK3=0,"",INDEX('Part types'!$X:$X,$AK3)&"") -> شورت بلوك | AJ3: =IF($AK3=0,"",INDEX('Part types'!$Y:$Y,$AK3)&"") | AK3: =IFERROR(MATCH($AD3,'Part types'!$E:$E,0),0) -> 3
A4: SKU1002 | B4: Engine | C4: Cylinder Block | D4: =C4&" - "&E4 -> Cylinder Block - Universal | E4: Universal | F4: Engine Block | G4: =IF($AK4=0,"",INDEX('Part types'!$P:$P,$AK4)) -> 60 | H4: =IF($AK4=0,"",INDEX('Part types'!$Q:$Q,$AK4)) -> 45 | I4: =IF($AK4=0,"",INDEX('Part types'!$R:$R,$AK4)) -> 40 | J4: =IF($AK4=0,"",INDEX('Part types'!$S:$S,$AK4)) -> 35 | K4: المحرك | L4: كتلة الأسطوانات | M4: =L4&" - "&N4 -> كتلة الأسطوانات - عام | N4: عام | O4: كتلة المحرك | P4: =G4 -> 60 | Q4: =H4 -> 45 | R4: =I4 -> 40 | S4: =J4 -> 35 | T4: 发动机 | U4: 气缸体 | V4: =U4&" - "&W4 -> 气缸体 - 通用 | W4: 通用 | X4: 缸体 | Y4: =G4 -> 60 | Z4: =H4 -> 45 | AA4: =I4 -> 40 | AB4: =J4 -> 35 | AC4: ENG | AD4: ENG-003 | AE4: =IF($AK4=0,"",INDEX('Part types'!$T:$T,$AK4)&"") -> Combustion engine (petrol, diesel, hybrid, range extender) | AF4: =IF($AK4=0,"",INDEX('Part types'!$U:$U,$AK4)&"") -> Heavy (over 30 kg) | AG4: =IF($AK4=0,"",INDEX('Part types'!$V:$V,$AK4)&"") -> Estimate: item-specific | AH4: =IF($AK4=0,"",INDEX('Part types'!$W:$W,$AK4)&"") | AI4: =IF($AK4=0,"",INDEX('Part types'!$X:$X,$AK4)&"") | AJ4: =IF($AK4=0,"",INDEX('Part types'!$Y:$Y,$AK4)&"") | AK4: =IFERROR(MATCH($AD4,'Part types'!$E:$E,0),0) -> 4
A5: SKU1003 | B5: Engine | C5: Cylinder Head | D5: =C5&" - "&E5 -> Cylinder Head - Universal | E5: Universal | F5: Cylinder Head | G5: =IF($AK5=0,"",INDEX('Part types'!$P:$P,$AK5)) -> 60 | H5: =IF($AK5=0,"",INDEX('Part types'!$Q:$Q,$AK5)) -> 30 | I5: =IF($AK5=0,"",INDEX('Part types'!$R:$R,$AK5)) -> 25 | J5: =IF($AK5=0,"",INDEX('Part types'!$S:$S,$AK5)) -> 18 | K5: المحرك | L5: رأس الأسطوانات | M5: =L5&" - "&N5 -> رأس الأسطوانات - عام | N5: عام | O5: رأس الأسطوانات | P5: =G5 -> 60 | Q5: =H5 -> 30 | R5: =I5 -> 25 | S5: =J5 -> 18 | T5: 发动机 | U5: 气缸盖 | V5: =U5&" - "&W5 -> 气缸盖 - 通用 | W5: 通用 | X5: 气缸盖 | Y5: =G5 -> 60 | Z5: =H5 -> 30 | AA5: =I5 -> 25 | AB5: =J5 -> 18 | AC5: ENG | AD5: ENG-004 | AE5: =IF($AK5=0,"",INDEX('Part types'!$T:$T,$AK5)&"") -> Combustion engine (petrol, diesel, hybrid, range extender) | AF5: =IF($AK5=0,"",INDEX('Part types'!$U:$U,$AK5)&"") | AG5: =IF($AK5=0,"",INDEX('Part types'!$V:$V,$AK5)&"") -> Estimate: item-specific | AH5: =IF($AK5=0,"",INDEX('Part types'!$W:$W,$AK5)&"") | AI5: =IF($AK5=0,"",INDEX('Part types'!$X:$X,$AK5)&"") | AJ5: =IF($AK5=0,"",INDEX('Part types'!$Y:$Y,$AK5)&"") | AK5: =IFERROR(MATCH($AD5,'Part types'!$E:$E,0),0) -> 5
A6: SKU1004 | B6: Engine | C6: Cylinder Head Gasket | D6: =C6&" - "&E6 -> Cylinder Head Gasket - Universal | E6: Universal | F6: Cylinder Head | G6: =IF($AK6=0,"",INDEX('Part types'!$P:$P,$AK6)) -> 50 | H6: =IF($AK6=0,"",INDEX('Part types'!$Q:$Q,$AK6)) -> 30 | I6: =IF($AK6=0,"",INDEX('Part types'!$R:$R,$AK6)) -> 3 | J6: =IF($AK6=0,"",INDEX('Part types'!$S:$S,$AK6)) -> 0.4 | K6: المحرك | L6: جوان رأس الأسطوانات | M6: =L6&" - "&N6 -> جوان رأس الأسطوانات - عام | N6: عام | O6: رأس الأسطوانات | P6: =G6 -> 50 | Q6: =H6 -> 30 | R6: =I6 -> 3 | S6: =J6 -> 0.4 | T6: 发动机 | U6: 气缸垫 | V6: =U6&" - "&W6 -> 气缸垫 - 通用 | W6: 通用 | X6: 气缸盖 | Y6: =G6 -> 50 | Z6: =H6 -> 30 | AA6: =I6 -> 3 | AB6: =J6 -> 0.4 | AC6: ENG | AD6: ENG-005 | AE6: =IF($AK6=0,"",INDEX('Part types'!$T:$T,$AK6)&"") -> Combustion engine (petrol, diesel, hybrid, range extender) | AF6: =IF($AK6=0,"",INDEX('Part types'!$U:$U,$AK6)&"") | AG6: =IF($AK6=0,"",INDEX('Part types'!$V:$V,$AK6)&"") -> Estimate: item-specific | AH6: =IF($AK6=0,"",INDEX('Part types'!$W:$W,$AK6)&"") | AI6: =IF($AK6=0,"",INDEX('Part types'!$X:$X,$AK6)&"") | AJ6: =IF($AK6=0,"",INDEX('Part types'!$Y:$Y,$AK6)&"") | AK6: =IFERROR(MATCH($AD6,'Part types'!$E:$E,0),0) -> 6
A7: SKU1005 | B7: Engine | C7: Head Bolt Set | D7: =C7&" - "&E7 -> Head Bolt Set - Universal | E7: Universal | F7: Cylinder Head | G7: =IF($AK7=0,"",INDEX('Part types'!$P:$P,$AK7)) -> 25 | H7: =IF($AK7=0,"",INDEX('Part types'!$Q:$Q,$AK7)) -> 15 | I7: =IF($AK7=0,"",INDEX('Part types'!$R:$R,$AK7)) -> 10 | J7: =IF($AK7=0,"",INDEX('Part types'!$S:$S,$AK7)) -> 0.9 | K7: المحرك | L7: طقم براغي رأس الأسطوانات | M7: =L7&" - "&N7 -> طقم براغي رأس الأسطوانات - عام | N7: عام | O7: رأس الأسطوانات | P7: =G7 -> 25 | Q7: =H7 -> 15 | R7: =I7 -> 10 | S7: =J7 -> 0.9 | T7: 发动机 | U7: 缸盖螺栓套装 | V7: =U7&" - "&W7 -> 缸盖螺栓套装 - 通用 | W7: 通用 | X7: 气缸盖 | Y7: =G7 -> 25 | Z7: =H7 -> 15 | AA7: =I7 -> 10 | AB7: =J7 -> 0.9 | AC7: ENG | AD7: ENG-006 | AE7: =IF($AK7=0,"",INDEX('Part types'!$T:$T,$AK7)&"") -> Combustion engine (petrol, diesel, hybrid, range extender) | AF7: =IF($AK7=0,"",INDEX('Part types'!$U:$U,$AK7)&"") | AG7: =IF($AK7=0,"",INDEX('Part types'!$V:$V,$AK7)&"") -> Estimate: size class M | AH7: =IF($AK7=0,"",INDEX('Part types'!$W:$W,$AK7)&"") -> Cylinder Head Bolt Set | AI7: =IF($AK7=0,"",INDEX('Part types'!$X:$X,$AK7)&"") | AJ7: =IF($AK7=0,"",INDEX('Part types'!$Y:$Y,$AK7)&"") | AK7: =IFERROR(MATCH($AD7,'Part types'!$E:$E,0),0) -> 7
A8: SKU1006 | B8: Engine | C8: Valve Cover | D8: =C8&" - "&E8 -> Valve Cover - Universal | E8: Universal | F8: Engine Top | G8: =IF($AK8=0,"",INDEX('Part types'!$P:$P,$AK8)) -> 40 | H8: =IF($AK8=0,"",INDEX('Part types'!$Q:$Q,$AK8)) -> 25 | I8: =IF($AK8=0,"",INDEX('Part types'!$R:$R,$AK8)) -> 15 | J8: =IF($AK8=0,"",INDEX('Part types'!$S:$S,$AK8)) -> 3 | K8: المحرك | L8: غطاء الصمامات | M8: =L8&" - "&N8 -> غطاء الصمامات - عام | N8: عام | O8: أعلى المحرك | P8: =G8 -> 40 | Q8: =H8 -> 25 | R8: =I8 -> 15 | S8: =J8 -> 3 | T8: 发动机 | U8: 气门室盖 | V8: =U8&" - "&W8 -> 气门室盖 - 通用 | W8: 通用 | X8: 发动机顶部 | Y8: =G8 -> 40 | Z8: =H8 -> 25 | AA8: =I8 -> 15 | AB8: =J8 -> 3 | AC8: ENG | AD8: ENG-007 | AE8: =IF($AK8=0,"",INDEX('Part types'!$T:$T,$AK8)&"") -> Combustion engine (petrol, diesel, hybrid, range extender) | AF8: =IF($AK8=0,"",INDEX('Part types'!$U:$U,$AK8)&"") | AG8: =IF($AK8=0,"",INDEX('Part types'!$V:$V,$AK8)&"") -> Estimate: size class L | AH8: =IF($AK8=0,"",INDEX('Part types'!$W:$W,$AK8)&"") | AI8: =IF($AK8=0,"",INDEX('Part types'!$X:$X,$AK8)&"") | AJ8: =IF($AK8=0,"",INDEX('Part types'!$Y:$Y,$AK8)&"") | AK8: =IFERROR(MATCH($AD8,'Part types'!$E:$E,0),0) -> 8
A9: SKU1007 | B9: Engine | C9: Valve Cover Gasket | D9: =C9&" - "&E9 -> Valve Cover Gasket - Universal | E9: Universal | F9: Engine Top | G9: =IF($AK9=0,"",INDEX('Part types'!$P:$P,$AK9)) -> 15 | H9: =IF($AK9=0,"",INDEX('Part types'!$Q:$Q,$AK9)) -> 10 | I9: =IF($AK9=0,"",INDEX('Part types'!$R:$R,$AK9)) -> 8 | J9: =IF($AK9=0,"",INDEX('Part types'!$S:$S,$AK9)) -> 0.3 | K9: المحرك | L9: جوان غطاء الصمامات | M9: =L9&" - "&N9 -> جوان غطاء الصمامات - عام | N9: عام | O9: أعلى المحرك | P9: =G9 -> 15 | Q9: =H9 -> 10 | R9: =I9 -> 8 | S9: =J9 -> 0.3 | T9: 发动机 | U9: 气门室盖垫 | V9: =U9&" - "&W9 -> 气门室盖垫 - 通用 | W9: 通用 | X9: 发动机顶部 | Y9: =G9 -> 15 | Z9: =H9 -> 10 | AA9: =I9 -> 8 | AB9: =J9 -> 0.3 | AC9: ENG | AD9: ENG-008 | AE9: =IF($AK9=0,"",INDEX('Part types'!$T:$T,$AK9)&"") -> Combustion engine (petrol, diesel, hybrid, range extender) | AF9: =IF($AK9=0,"",INDEX('Part types'!$U:$U,$AK9)&"") | AG9: =IF($AK9=0,"",INDEX('Part types'!$V:$V,$AK9)&"") -> Estimate: size class S | AH9: =IF($AK9=0,"",INDEX('Part types'!$W:$W,$AK9)&"") | AI9: =IF($AK9=0,"",INDEX('Part types'!$X:$X,$AK9)&"") | AJ9: =IF($AK9=0,"",INDEX('Part types'!$Y:$Y,$AK9)&"") | AK9: =IFERROR(MATCH($AD9,'Part types'!$E:$E,0),0) -> 9
A10: SKU1008 | B10: Engine | C10: Piston | D10: =C10&" - "&E10 -> Piston - Universal | E10: Universal | F10: Engine Internal | G10: =IF($AK10=0,"",INDEX('Part types'!$P:$P,$AK10)) -> 10 | H10: =IF($AK10=0,"",INDEX('Part types'!$Q:$Q,$AK10)) -> 8 | I10: =IF($AK10=0,"",INDEX('Part types'!$R:$R,$AK10)) -> 6 | J10: =IF($AK10=0,"",INDEX('Part types'!$S:$S,$AK10)) -> 0.1 | K10: المحرك | L10: مكبس | M10: =L10&" - "&N10 -> مكبس - عام | N10: عام | O10: داخل المحرك | P10: =G10 -> 10 | Q10: =H10 -> 8 | R10: =I10 -> 6 | S10: =J10 -> 0.1 | T10: 发动机 | U10: 活塞 | V10: =U10&" - "&W10 -> 活塞 - 通用 | W10: 通用 | X10: 发动机内部 | Y10: =G10 -> 10 | Z10: =H10 -> 8 | AA10: =I10 -> 6 | AB10: =J10 -> 0.1 | AC10: ENG | AD10: ENG-009 | AE10: =IF($AK10=0,"",INDEX('Part types'!$T:$T,$AK10)&"") -> Combustion engine (petrol, diesel, hybrid, range extender) | AF10: =IF($AK10=0,"",INDEX('Part types'!$U:$U,$AK10)&"") | AG10: =IF($AK10=0,"",INDEX('Part types'!$V:$V,$AK10)&"") -> Estimate: size class XS | AH10: =IF($AK10=0,"",INDEX('Part types'!$W:$W,$AK10)&"") | AI10: =IF($AK10=0,"",INDEX('Part types'!$X:$X,$AK10)&"") -> بستم | AJ10: =IF($AK10=0,"",INDEX('Part types'!$Y:$Y,$AK10)&"") | AK10: =IFERROR(MATCH($AD10,'Part types'!$E:$E,0),0) -> 10
A11: SKU1009 | B11: Engine | C11: Piston Ring Set | D11: =C11&" - "&E11 -> Piston Ring Set - Universal | E11: Universal | F11: Engine Internal | G11: =IF($AK11=0,"",INDEX('Part types'!$P:$P,$AK11)) -> 15 | H11: =IF($AK11=0,"",INDEX('Part types'!$Q:$Q,$AK11)) -> 10 | I11: =IF($AK11=0,"",INDEX('Part types'!$R:$R,$AK11)) -> 8 | J11: =IF($AK11=0,"",INDEX('Part types'!$S:$S,$AK11)) -> 0.3 | K11: المحرك | L11: طقم شنابر المكبس | M11: =L11&" - "&N11 -> طقم شنابر المكبس - عام | N11: عام | O11: داخل المحرك | P11: =G11 -> 15 | Q11: =H11 -> 10 | R11: =I11 -> 8 | S11: =J11 -> 0.3 | T11: 发动机 | U11: 活塞环套装 | V11: =U11&" - "&W11 -> 活塞环套装 - 通用 | W11: 通用 | X11: 发动机内部 | Y11: =G11 -> 15 | Z11: =H11 -> 10 | AA11: =I11 -> 8 | AB11: =J11 -> 0.3 | AC11: ENG | AD11: ENG-010 | AE11: =IF($AK11=0,"",INDEX('Part types'!$T:$T,$AK11)&"") -> Combustion engine (petrol, diesel, hybrid, range extender) | AF11: =IF($AK11=0,"",INDEX('Part types'!$U:$U,$AK11)&"") | AG11: =IF($AK11=0,"",INDEX('Part types'!$V:$V,$AK11)&"") -> Estimate: size class S | AH11: =IF($AK11=0,"",INDEX('Part types'!$W:$W,$AK11)&"") | AI11: =IF($AK11=0,"",INDEX('Part types'!$X:$X,$AK11)&"") | AJ11: =IF($AK11=0,"",INDEX('Part types'!$Y:$Y,$AK11)&"") | AK11: =IFERROR(MATCH($AD11,'Part types'!$E:$E,0),0) -> 11
A12: SKU1010 | B12: Engine | C12: Piston Pin | D12: =C12&" - "&E12 -> Piston Pin - Universal | E12: Universal | F12: Engine Internal | G12: =IF($AK12=0,"",INDEX('Part types'!$P:$P,$AK12)) -> 10 | H12: =IF($AK12=0,"",INDEX('Part types'!$Q:$Q,$AK12)) -> 8 | I12: =IF($AK12=0,"",INDEX('Part types'!$R:$R,$AK12)) -> 6 | J12: =IF($AK12=0,"",INDEX('Part types'!$S:$S,$AK12)) -> 0.1 | K12: المحرك | L12: مسمار المكبس | M12: =L12&" - "&N12 -> مسمار المكبس - عام | N12: عام | O12: داخل المحرك | P12: =G12 -> 10 | Q12: =H12 -> 8 | R12: =I12 -> 6 | S12: =J12 -> 0.1 | T12: 发动机 | U12: 活塞销 | V12: =U12&" - "&W12 -> 活塞销 - 通用 | W12: 通用 | X12: 发动机内部 | Y12: =G12 -> 10 | Z12: =H12 -> 8 | AA12: =I12 -> 6 | AB12: =J12 -> 0.1 | AC12: ENG | AD12: ENG-011 | AE12: =IF($AK12=0,"",INDEX('Part types'!$T:$T,$AK12)&"") -> Combustion engine (petrol, diesel, hybrid, range extender) | AF12: =IF($AK12=0,"",INDEX('Part types'!$U:$U,$AK12)&"") | AG12: =IF($AK12=0,"",INDEX('Part types'!$V:$V,$AK12)&"") -> Estimate: size class XS | AH12: =IF($AK12=0,"",INDEX('Part types'!$W:$W,$AK12)&"") | AI12: =IF($AK12=0,"",INDEX('Part types'!$X:$X,$AK12)&"") | AJ12: =IF($AK12=0,"",INDEX('Part types'!$Y:$Y,$AK12)&"") | AK12: =IFERROR(MATCH($AD12,'Part types'!$E:$E,0),0) -> 12
A13: SKU1011 | B13: Engine | C13: Connecting Rod | D13: =C13&" - "&E13 -> Connecting Rod - Universal | E13: Universal | F13: Engine Internal | G13: =IF($AK13=0,"",INDEX('Part types'!$P:$P,$AK13)) -> 15 | H13: =IF($AK13=0,"",INDEX('Part types'!$Q:$Q,$AK13)) -> 10 | I13: =IF($AK13=0,"",INDEX('Part types'!$R:$R,$AK13)) -> 8 | J13: =IF($AK13=0,"",INDEX('Part types'!$S:$S,$AK13)) -> 0.3 | K13: المحرك | L13: ذراع التوصيل | M13: =L13&" - "&N13 -> ذراع التوصيل - عام | N13: عام | O13: داخل المحرك | P13: =G13 -> 15 | Q13: =H13 -> 10 | R13: =I13 -> 8 | S13: =J13 -> 0.3 | T13: 发动机 | U13: 连杆 | V13: =U13&" - "&W13 -> 连杆 - 通用 | W13: 通用 | X13: 发动机内部 | Y13: =G13 -> 15 | Z13: =H13 -> 10 | AA13: =I13 -> 8 | AB13: =J13 -> 0.3 | AC13: ENG | AD13: ENG-012 | AE13: =IF($AK13=0,"",INDEX('Part types'!$T:$T,$AK13)&"") -> Combustion engine (petrol, diesel, hybrid, range extender) | AF13: =IF($AK13=0,"",INDEX('Part types'!$U:$U,$AK13)&"") | AG13: =IF($AK13=0,"",INDEX('Part types'!$V:$V,$AK13)&"") -> Estimate: size class S | AH13: =IF($AK13=0,"",INDEX('Part types'!$W:$W,$AK13)&"") | AI13: =IF($AK13=0,"",INDEX('Part types'!$X:$X,$AK13)&"") -> البيل | AJ13: =IF($AK13=0,"",INDEX('Part types'!$Y:$Y,$AK13)&"") | AK13: =IFERROR(MATCH($AD13,'Part types'!$E:$E,0),0) -> 13
... A161: SKU1159 | B161: Filters | C161: Battery Coolant Filter | D161: =C161&" - "&E161 -> Battery Coolant Filter - Universal | E161: Universal | F161: HV Battery Pack | G161: =IF($AK161=0,"",INDEX('Part types'!$P:$P,$AK161)) -> 15 | H161: =IF($AK161=0,"",INDEX('Part types'!$Q:$Q,$AK161)) -> 10 | I161: =IF($AK161=0,"",INDEX('Part types'!$R:$R,$AK161)) -> 8 | J161: =IF($AK161=0,"",INDEX('Part types'!$S:$S,$AK161)) -> 0.3 | K161: الفلاتر | L161: فلتر سائل تبريد البطارية | M161: =L161&" - "&N161 -> فلتر سائل تبريد البطارية - عام | N161: عام | O161: حزمة بطارية الجهد العالي | P161: =G161 -> 15 | Q161: =H161 -> 10 | R161: =I161 -> 8 | S161: =J161 -> 0.3 | T161: 滤清器 | U161: 电池冷却液滤清器 | V161: =U161&" - "&W161 -> 电池冷却液滤清器 - 通用 | W161: 通用 | X161: 高压电池包 | Y161: =G161 -> 15 | Z161: =H161 -> 10 | AA161: =I161 -> 8 | AB161: =J161 -> 0.3 | AC161: FLT | AD161: FLT-013 | AE161: =IF($AK161=0,"",INDEX('Part types'!$T:$T,$AK161)&"") -> Electrified (hybrid, plug-in, range extender, EV) | AF161: =IF($AK161=0,"",INDEX('Part types'!$U:$U,$AK161)&"") | AG161: =IF($AK161=0,"",INDEX('Part types'!$V:$V,$AK161)&"") -> Estimate: size class S | AH161: =IF($AK161=0,"",INDEX('Part types'!$W:$W,$AK161)&"") | AI161: =IF($AK161=0,"",INDEX('Part types'!$X:$X,$AK161)&"") | AJ161: =IF($AK161=0,"",INDEX('Part types'!$Y:$Y,$AK161)&"") | AK161: =IFERROR(MATCH($AD161,'Part types'!$E:$E,0),0) -> 155
A162: SKU1160 | B162: Fluids | C162: Engine Oil | D162: =C162&" "&INDEX('Part types'!$I:$I,$AK162) -> Engine Oil 1 L | E162: Universal | F162: Universal Fit | G162: =IF($AK162=0,"",INDEX('Part types'!$P:$P,$AK162)) -> 10 | H162: =IF($AK162=0,"",INDEX('Part types'!$Q:$Q,$AK162)) -> 8 | I162: =IF($AK162=0,"",INDEX('Part types'!$R:$R,$AK162)) -> 24 | J162: =IF($AK162=0,"",INDEX('Part types'!$S:$S,$AK162)) -> 0.95 | K162: السوائل | L162: زيت محرك | M162: =L162&" "&INDEX('Part types'!$J:$J,$AK162) -> زيت محرك 1 لتر | N162: عام | O162: تركيب عام | P162: =G162 -> 10 | Q162: =H162 -> 8 | R162: =I162 -> 24 | S162: =J162 -> 0.95 | T162: 油液 | U162: 发动机机油 | V162: =U162&" "&INDEX('Part types'!$K:$K,$AK162) -> 发动机机油 1升 | W162: 通用 | X162: 通用安装 | Y162: =G162 -> 10 | Z162: =H162 -> 8 | AA162: =I162 -> 24 | AB162: =J162 -> 0.95 | AC162: FLD | AD162: FLD-001 | AE162: =IF($AK162=0,"",INDEX('Part types'!$T:$T,$AK162)&"") -> Combustion engine (petrol, diesel, hybrid, range extender) | AF162: =IF($AK162=0,"",INDEX('Part types'!$U:$U,$AK162)&"") -> Liquid / flammable | AG162: =IF($AK162=0,"",INDEX('Part types'!$V:$V,$AK162)&"") -> Estimate: item-specific | AH162: =IF($AK162=0,"",INDEX('Part types'!$W:$W,$AK162)&"") | AI162: =IF($AK162=0,"",INDEX('Part types'!$X:$X,$AK162)&"") | AJ162: =IF($AK162=0,"",INDEX('Part types'!$Y:$Y,$AK162)&"") | AK162: =IFERROR(MATCH($AD162,'Part types'!$E:$E,0),0) -> 156
A163: SKU1161 | B163: Fluids | C163: Engine Oil | D163: =C163&" "&INDEX('Part types'!$I:$I,$AK163) -> Engine Oil 4 L | E163: Universal | F163: Universal Fit | G163: =IF($AK163=0,"",INDEX('Part types'!$P:$P,$AK163)) -> 20 | H163: =IF($AK163=0,"",INDEX('Part types'!$Q:$Q,$AK163)) -> 12 | I163: =IF($AK163=0,"",INDEX('Part types'!$R:$R,$AK163)) -> 28 | J163: =IF($AK163=0,"",INDEX('Part types'!$S:$S,$AK163)) -> 3.7 | K163: السوائل | L163: زيت محرك | M163: =L163&" "&INDEX('Part types'!$J:$J,$AK163) -> زيت محرك 4 لتر | N163: عام | O163: تركيب عام | P163: =G163 -> 20 | Q163: =H163 -> 12 | R163: =I163 -> 28 | S163: =J163 -> 3.7 | T163: 油液 | U163: 发动机机油 | V163: =U163&" "&INDEX('Part types'!$K:$K,$AK163) -> 发动机机油 4升 | W163: 通用 | X163: 通用安装 | Y163: =G163 -> 20 | Z163: =H163 -> 12 | AA163: =I163 -> 28 | AB163: =J163 -> 3.7 | AC163: FLD | AD163: FLD-002 | AE163: =IF($AK163=0,"",INDEX('Part types'!$T:$T,$AK163)&"") -> Combustion engine (petrol, diesel, hybrid, range extender) | AF163: =IF($AK163=0,"",INDEX('Part types'!$U:$U,$AK163)&"") -> Liquid / flammable | AG163: =IF($AK163=0,"",INDEX('Part types'!$V:$V,$AK163)&"") -> Estimate: item-specific | AH163: =IF($AK163=0,"",INDEX('Part types'!$W:$W,$AK163)&"") | AI163: =IF($AK163=0,"",INDEX('Part types'!$X:$X,$AK163)&"") | AJ163: =IF($AK163=0,"",INDEX('Part types'!$Y:$Y,$AK163)&"") | AK163: =IFERROR(MATCH($AD163,'Part types'!$E:$E,0),0) -> 157
A164: SKU1162 | B164: Fluids | C164: Engine Oil | D164: =C164&" "&INDEX('Part types'!$I:$I,$AK164) -> Engine Oil 5 L | E164: Universal | F164: Universal Fit | G164: =IF($AK164=0,"",INDEX('Part types'!$P:$P,$AK164)) -> 22 | H164: =IF($AK164=0,"",INDEX('Part types'!$Q:$Q,$AK164)) -> 14 | I164: =IF($AK164=0,"",INDEX('Part types'!$R:$R,$AK164)) -> 28 | J164: =IF($AK164=0,"",INDEX('Part types'!$S:$S,$AK164)) -> 4.6 | K164: السوائل | L164: زيت محرك | M164: =L164&" "&INDEX('Part types'!$J:$J,$AK164) -> زيت محرك 5 لتر | N164: عام | O164: تركيب عام | P164: =G164 -> 22 | Q164: =H164 -> 14 | R164: =I164 -> 28 | S164: =J164 -> 4.6 | T164: 油液 | U164: 发动机机油 | V164: =U164&" "&INDEX('Part types'!$K:$K,$AK164) -> 发动机机油 5升 | W164: 通用 | X164: 通用安装 | Y164: =G164 -> 22 | Z164: =H164 -> 14 | AA164: =I164 -> 28 | AB164: =J164 -> 4.6 | AC164: FLD | AD164: FLD-003 | AE164: =IF($AK164=0,"",INDEX('Part types'!$T:$T,$AK164)&"") -> Combustion engine (petrol, diesel, hybrid, range extender) | AF164: =IF($AK164=0,"",INDEX('Part types'!$U:$U,$AK164)&"") -> Liquid / flammable | AG164: =IF($AK164=0,"",INDEX('Part types'!$V:$V,$AK164)&"") -> Estimate: item-specific | AH164: =IF($AK164=0,"",INDEX('Part types'!$W:$W,$AK164)&"") | AI164: =IF($AK164=0,"",INDEX('Part types'!$X:$X,$AK164)&"") | AJ164: =IF($AK164=0,"",INDEX('Part types'!$Y:$Y,$AK164)&"") | AK164: =IFERROR(MATCH($AD164,'Part types'!$E:$E,0),0) -> 158
A165: SKU1163 | B165: Fluids | C165: Automatic Transmission Fluid | D165: =C165&" "&INDEX('Part types'!$I:$I,$AK165) -> Automatic Transmission Fluid 1 L | E165: Universal | F165: Universal Fit | G165: =IF($AK165=0,"",INDEX('Part types'!$P:$P,$AK165)) -> 10 | H165: =IF($AK165=0,"",INDEX('Part types'!$Q:$Q,$AK165)) -> 8 | I165: =IF($AK165=0,"",INDEX('Part types'!$R:$R,$AK165)) -> 24 | J165: =IF($AK165=0,"",INDEX('Part types'!$S:$S,$AK165)) -> 0.95 | K165: السوائل | L165: زيت ناقل حركة أوتوماتيك | M165: =L165&" "&INDEX('Part types'!$J:$J,$AK165) -> زيت ناقل حركة أوتوماتيك 1 لتر | N165: عام | O165: تركيب عام | P165: =G165 -> 10 | Q165: =H165 -> 8 | R165: =I165 -> 24 | S165: =J165 -> 0.95 | T165: 油液 | U165: 自动变速箱油 | V165: =U165&" "&INDEX('Part types'!$K:$K,$AK165) -> 自动变速箱油 1升 | W165: 通用 | X165: 通用安装 | Y165: =G165 -> 10 | Z165: =H165 -> 8 | AA165: =I165 -> 24 | AB165: =J165 -> 0.95 | AC165: FLD | AD165: FLD-004 | AE165: =IF($AK165=0,"",INDEX('Part types'!$T:$T,$AK165)&"") -> Combustion engine (petrol, diesel, hybrid, range extender) | AF165: =IF($AK165=0,"",INDEX('Part types'!$U:$U,$AK165)&"") -> Liquid / flammable | AG165: =IF($AK165=0,"",INDEX('Part types'!$V:$V,$AK165)&"") -> Estimate: item-specific | AH165: =IF($AK165=0,"",INDEX('Part types'!$W:$W,$AK165)&"") -> Automatic Transmission Fluid ATF | AI165: =IF($AK165=0,"",INDEX('Part types'!$X:$X,$AK165)&"") | AJ165: =IF($AK165=0,"",INDEX('Part types'!$Y:$Y,$AK165)&"") | AK165: =IFERROR(MATCH($AD165,'Part types'!$E:$E,0),0) -> 159
A166: SKU1164 | B166: Fluids | C166: Automatic Transmission Fluid | D166: =C166&" "&INDEX('Part types'!$I:$I,$AK166) -> Automatic Transmission Fluid 4 L | E166: Universal | F166: Universal Fit | G166: =IF($AK166=0,"",INDEX('Part types'!$P:$P,$AK166)) -> 20 | H166: =IF($AK166=0,"",INDEX('Part types'!$Q:$Q,$AK166)) -> 12 | I166: =IF($AK166=0,"",INDEX('Part types'!$R:$R,$AK166)) -> 28 | J166: =IF($AK166=0,"",INDEX('Part types'!$S:$S,$AK166)) -> 3.7 | K166: السوائل | L166: زيت ناقل حركة أوتوماتيك | M166: =L166&" "&INDEX('Part types'!$J:$J,$AK166) -> زيت ناقل حركة أوتوماتيك 4 لتر | N166: عام | O166: تركيب عام | P166: =G166 -> 20 | Q166: =H166 -> 12 | R166: =I166 -> 28 | S166: =J166 -> 3.7 | T166: 油液 | U166: 自动变速箱油 | V166: =U166&" "&INDEX('Part types'!$K:$K,$AK166) -> 自动变速箱油 4升 | W166: 通用 | X166: 通用安装 | Y166: =G166 -> 20 | Z166: =H166 -> 12 | AA166: =I166 -> 28 | AB166: =J166 -> 3.7 | AC166: FLD | AD166: FLD-005 | AE166: =IF($AK166=0,"",INDEX('Part types'!$T:$T,$AK166)&"") -> Combustion engine (petrol, diesel, hybrid, range extender) | AF166: =IF($AK166=0,"",INDEX('Part types'!$U:$U,$AK166)&"") -> Liquid / flammable | AG166: =IF($AK166=0,"",INDEX('Part types'!$V:$V,$AK166)&"") -> Estimate: item-specific | AH166: =IF($AK166=0,"",INDEX('Part types'!$W:$W,$AK166)&"") -> Automatic Transmission Fluid ATF | AI166: =IF($AK166=0,"",INDEX('Part types'!$X:$X,$AK166)&"") | AJ166: =IF($AK166=0,"",INDEX('Part types'!$Y:$Y,$AK166)&"") | AK166: =IFERROR(MATCH($AD166,'Part types'!$E:$E,0),0) -> 160
A167: SKU1165 | B167: Fluids | C167: CVT Fluid | D167: =C167&" "&INDEX('Part types'!$I:$I,$AK167) -> CVT Fluid 4 L | E167: Universal | F167: Universal Fit | G167: =IF($AK167=0,"",INDEX('Part types'!$P:$P,$AK167)) -> 20 | H167: =IF($AK167=0,"",INDEX('Part types'!$Q:$Q,$AK167)) -> 12 | I167: =IF($AK167=0,"",INDEX('Part types'!$R:$R,$AK167)) -> 28 | J167: =IF($AK167=0,"",INDEX('Part types'!$S:$S,$AK167)) -> 3.7 | K167: السوائل | L167: زيت ناقل حركة CVT | M167: =L167&" "&INDEX('Part types'!$J:$J,$AK167) -> زيت ناقل حركة CVT 4 لتر | N167: عام | O167: تركيب عام | P167: =G167 -> 20 | Q167: =H167 -> 12 | R167: =I167 -> 28 | S167: =J167 -> 3.7 | T167: 油液 | U167: CVT变速箱油 | V167: =U167&" "&INDEX('Part types'!$K:$K,$AK167) -> CVT变速箱油 4升 | W167: 通用 | X167: 通用安装 | Y167: =G167 -> 20 | Z167: =H167 -> 12 | AA167: =I167 -> 28 | AB167: =J167 -> 3.7 | AC167: FLD | AD167: FLD-006 | AE167: =IF($AK167=0,"",INDEX('Part types'!$T:$T,$AK167)&"") -> Combustion engine (petrol, diesel, hybrid, range extender) | AF167: =IF($AK167=0,"",INDEX('Part types'!$U:$U,$AK167)&"") -> Liquid / flammable | AG167: =IF($AK167=0,"",INDEX('Part types'!$V:$V,$AK167)&"") -> Estimate: item-specific | AH167: =IF($AK167=0,"",INDEX('Part types'!$W:$W,$AK167)&"") | AI167: =IF($AK167=0,"",INDEX('Part types'!$X:$X,$AK167)&"") | AJ167: =IF($AK167=0,"",INDEX('Part types'!$Y:$Y,$AK167)&"") | AK167: =IFERROR(MATCH($AD167,'Part types'!$E:$E,0),0) -> 161
A168: SKU1166 | B168: Fluids | C168: Manual Gear Oil | D168: =C168&" "&INDEX('Part types'!$I:$I,$AK168) -> Manual Gear Oil 1 L | E168: Universal | F168: Universal Fit | G168: =IF($AK168=0,"",INDEX('Part types'!$P:$P,$AK168)) -> 10 | H168: =IF($AK168=0,"",INDEX('Part types'!$Q:$Q,$AK168)) -> 8 | I168: =IF($AK168=0,"",INDEX('Part types'!$R:$R,$AK168)) -> 24 | J168: =IF($AK168=0,"",INDEX('Part types'!$S:$S,$AK168)) -> 0.95 | K168: السوائل | L168: زيت قير عادي | M168: =L168&" "&INDEX('Part types'!$J:$J,$AK168) -> زيت قير عادي 1 لتر | N168: عام | O168: تركيب عام | P168: =G168 -> 10 | Q168: =H168 -> 8 | R168: =I168 -> 24 | S168: =J168 -> 0.95 | T168: 油液 | U168: 手动变速箱油 | V168: =U168&" "&INDEX('Part types'!$K:$K,$AK168) -> 手动变速箱油 1升 | W168: 通用 | X168: 通用安装 | Y168: =G168 -> 10 | Z168: =H168 -> 8 | AA168: =I168 -> 24 | AB168: =J168 -> 0.95 | AC168: FLD | AD168: FLD-007 | AE168: =IF($AK168=0,"",INDEX('Part types'!$T:$T,$AK168)&"") -> Combustion engine (petrol, diesel, hybrid, range extender) | AF168: =IF($AK168=0,"",INDEX('Part types'!$U:$U,$AK168)&"") -> Liquid / flammable | AG168: =IF($AK168=0,"",INDEX('Part types'!$V:$V,$AK168)&"") -> Estimate: item-specific | AH168: =IF($AK168=0,"",INDEX('Part types'!$W:$W,$AK168)&"") | AI168: =IF($AK168=0,"",INDEX('Part types'!$X:$X,$AK168)&"") | AJ168: =IF($AK168=0,"",INDEX('Part types'!$Y:$Y,$AK168)&"") | AK168: =IFERROR(MATCH($AD168,'Part types'!$E:$E,0),0) -> 162
A169: SKU1167 | B169: Fluids | C169: Differential Oil | D169: =C169&" "&INDEX('Part types'!$I:$I,$AK169) -> Differential Oil 1 L | E169: Universal | F169: Universal Fit | G169: =IF($AK169=0,"",INDEX('Part types'!$P:$P,$AK169)) -> 10 | H169: =IF($AK169=0,"",INDEX('Part types'!$Q:$Q,$AK169)) -> 8 | I169: =IF($AK169=0,"",INDEX('Part types'!$R:$R,$AK169)) -> 24 | J169: =IF($AK169=0,"",INDEX('Part types'!$S:$S,$AK169)) -> 0.95 | K169: السوائل | L169: زيت الدفرنس | M169: =L169&" "&INDEX('Part types'!$J:$J,$AK169) -> زيت الدفرنس 1 لتر | N169: عام | O169: تركيب عام | P169: =G169 -> 10 | Q169: =H169 -> 8 | R169: =I169 -> 24 | S169: =J169 -> 0.95 | T169: 油液 | U169: 差速器油 | V169: =U169&" "&INDEX('Part types'!$K:$K,$AK169) -> 差速器油 1升 | W169: 通用 | X169: 通用安装 | Y169: =G169 -> 10 | Z169: =H169 -> 8 | AA169: =I169 -> 24 | AB169: =J169 -> 0.95 | AC169: FLD | AD169: FLD-008 | AE169: =IF($AK169=0,"",INDEX('Part types'!$T:$T,$AK169)&"") -> All vehicles | AF169: =IF($AK169=0,"",INDEX('Part types'!$U:$U,$AK169)&"") -> Liquid / flammable | AG169: =IF($AK169=0,"",INDEX('Part types'!$V:$V,$AK169)&"") -> Estimate: item-specific | AH169: =IF($AK169=0,"",INDEX('Part types'!$W:$W,$AK169)&"") -> Differential Gear Oil | AI169: =IF($AK169=0,"",INDEX('Part types'!$X:$X,$AK169)&"") | AJ169: =IF($AK169=0,"",INDEX('Part types'!$Y:$Y,$AK169)&"") | AK169: =IFERROR(MATCH($AD169,'Part types'!$E:$E,0),0) -> 163
A170: SKU1168 | B170: Fluids | C170: EV Gear Oil | D170: =C170&" "&INDEX('Part types'!$I:$I,$AK170) -> EV Gear Oil 1 L | E170: Universal | F170: Universal Fit | G170: =IF($AK170=0,"",INDEX('Part types'!$P:$P,$AK170)) -> 10 | H170: =IF($AK170=0,"",INDEX('Part types'!$Q:$Q,$AK170)) -> 8 | I170: =IF($AK170=0,"",INDEX('Part types'!$R:$R,$AK170)) -> 24 | J170: =IF($AK170=0,"",INDEX('Part types'!$S:$S,$AK170)) -> 0.95 | K170: السوائل | L170: زيت علبة تخفيض السرعة للسيارات الكهربائية | M170: =L170&" "&INDEX('Part types'!$J:$J,$AK170) -> زيت علبة تخفيض السرعة للسيارات الكهربائية 1 لتر | N170: عام | O170: تركيب عام | P170: =G170 -> 10 | Q170: =H170 -> 8 | R170: =I170 -> 24 | S170: =J170 -> 0.95 | T170: 油液 | U170: 电动车减速器油 | V170: =U170&" "&INDEX('Part types'!$K:$K,$AK170) -> 电动车减速器油 1升 | W170: 通用 | X170: 通用安装 | Y170: =G170 -> 10 | Z170: =H170 -> 8 | AA170: =I170 -> 24 | AB170: =J170 -> 0.95 | AC170: FLD | AD170: FLD-009 | AE170: =IF($AK170=0,"",INDEX('Part types'!$T:$T,$AK170)&"") -> Electrified (hybrid, plug-in, range extender, EV) | AF170: =IF($AK170=0,"",INDEX('Part types'!$U:$U,$AK170)&"") -> Liquid / flammable | AG170: =IF($AK170=0,"",INDEX('Part types'!$V:$V,$AK170)&"") -> Estimate: item-specific | AH170: =IF($AK170=0,"",INDEX('Part types'!$W:$W,$AK170)&"") -> Reduction Gear Oil for EV | AI170: =IF($AK170=0,"",INDEX('Part types'!$X:$X,$AK170)&"") | AJ170: =IF($AK170=0,"",INDEX('Part types'!$Y:$Y,$AK170)&"") | AK170: =IFERROR(MATCH($AD170,'Part types'!$E:$E,0),0) -> 164
A171: SKU1169 | B171: Fluids | C171: Brake Fluid | D171: =C171&" "&INDEX('Part types'!$I:$I,$AK171) -> Brake Fluid DOT4 500 ml | E171: Universal | F171: Universal Fit | G171: =IF($AK171=0,"",INDEX('Part types'!$P:$P,$AK171)) -> 8 | H171: =IF($AK171=0,"",INDEX('Part types'!$Q:$Q,$AK171)) -> 8 | I171: =IF($AK171=0,"",INDEX('Part types'!$R:$R,$AK171)) -> 20 | J171: =IF($AK171=0,"",INDEX('Part types'!$S:$S,$AK171)) -> 0.55 | K171: السوائل | L171: زيت فرامل | M171: =L171&" "&INDEX('Part types'!$J:$J,$AK171) -> زيت فرامل DOT4 500 مل | N171: عام | O171: تركيب عام | P171: =G171 -> 8 | Q171: =H171 -> 8 | R171: =I171 -> 20 | S171: =J171 -> 0.55 | T171: 油液 | U171: 制动液 | V171: =U171&" "&INDEX('Part types'!$K:$K,$AK171) -> 制动液 DOT4 500毫升 | W171: 通用 | X171: 通用安装 | Y171: =G171 -> 8 | Z171: =H171 -> 8 | AA171: =I171 -> 20 | AB171: =J171 -> 0.55 | AC171: FLD | AD171: FLD-010 | AE171: =IF($AK171=0,"",INDEX('Part types'!$T:$T,$AK171)&"") -> All vehicles | AF171: =IF($AK171=0,"",INDEX('Part types'!$U:$U,$AK171)&"") -> Liquid / flammable | AG171: =IF($AK171=0,"",INDEX('Part types'!$V:$V,$AK171)&"") -> Estimate: item-specific | AH171: =IF($AK171=0,"",INDEX('Part types'!$W:$W,$AK171)&"") -> Brake Fluid DOT 4 | AI171: =IF($AK171=0,"",INDEX('Part types'!$X:$X,$AK171)&"") | AJ171: =IF($AK171=0,"",INDEX('Part types'!$Y:$Y,$AK171)&"") | AK171: =IFERROR(MATCH($AD171,'Part types'!$E:$E,0),0) -> 165
A172: SKU1170 | B172: Fluids | C172: Coolant | D172: =C172&" "&INDEX('Part types'!$I:$I,$AK172) -> Coolant Antifreeze 4 L | E172: Universal | F172: Universal Fit | G172: =IF($AK172=0,"",INDEX('Part types'!$P:$P,$AK172)) -> 20 | H172: =IF($AK172=0,"",INDEX('Part types'!$Q:$Q,$AK172)) -> 12 | I172: =IF($AK172=0,"",INDEX('Part types'!$R:$R,$AK172)) -> 28 | J172: =IF($AK172=0,"",INDEX('Part types'!$S:$S,$AK172)) -> 4.2 | K172: السوائل | L172: سائل تبريد | M172: =L172&" "&INDEX('Part types'!$J:$J,$AK172) -> سائل تبريد مضاد للتجمد 4 لتر | N172: عام | O172: تركيب عام | P172: =G172 -> 20 | Q172: =H172 -> 12 | R172: =I172 -> 28 | S172: =J172 -> 4.2 | T172: 油液 | U172: 冷却液 | V172: =U172&" "&INDEX('Part types'!$K:$K,$AK172) -> 冷却液 防冻液 4升 | W172: 通用 | X172: 通用安装 | Y172: =G172 -> 20 | Z172: =H172 -> 12 | AA172: =I172 -> 28 | AB172: =J172 -> 4.2 | AC172: FLD | AD172: FLD-011 | AE172: =IF($AK172=0,"",INDEX('Part types'!$T:$T,$AK172)&"") -> All vehicles | AF172: =IF($AK172=0,"",INDEX('Part types'!$U:$U,$AK172)&"") -> Liquid / flammable | AG172: =IF($AK172=0,"",INDEX('Part types'!$V:$V,$AK172)&"") -> Estimate: item-specific | AH172: =IF($AK172=0,"",INDEX('Part types'!$W:$W,$AK172)&"") -> Coolant Antifreeze | AI172: =IF($AK172=0,"",INDEX('Part types'!$X:$X,$AK172)&"") | AJ172: =IF($AK172=0,"",INDEX('Part types'!$Y:$Y,$AK172)&"") | AK172: =IFERROR(MATCH($AD172,'Part types'!$E:$E,0),0) -> 166
A173: SKU1171 | B173: Fluids | C173: Coolant | D173: =C173&" "&INDEX('Part types'!$I:$I,$AK173) -> Coolant Concentrate 1 L | E173: Universal | F173: Universal Fit | G173: =IF($AK173=0,"",INDEX('Part types'!$P:$P,$AK173)) -> 10 | H173: =IF($AK173=0,"",INDEX('Part types'!$Q:$Q,$AK173)) -> 8 | I173: =IF($AK173=0,"",INDEX('Part types'!$R:$R,$AK173)) -> 24 | J173: =IF($AK173=0,"",INDEX('Part types'!$S:$S,$AK173)) -> 1.1 | K173: السوائل | L173: سائل تبريد | M173: =L173&" "&INDEX('Part types'!$J:$J,$AK173) -> سائل تبريد مركز 1 لتر | N173: عام | O173: تركيب عام | P173: =G173 -> 10 | Q173: =H173 -> 8 | R173: =I173 -> 24 | S173: =J173 -> 1.1 | T173: 油液 | U173: 冷却液 | V173: =U173&" "&INDEX('Part types'!$K:$K,$AK173) -> 冷却液 浓缩液 1升 | W173: 通用 | X173: 通用安装 | Y173: =G173 -> 10 | Z173: =H173 -> 8 | AA173: =I173 -> 24 | AB173: =J173 -> 1.1 | AC173: FLD | AD173: FLD-012 | AE173: =IF($AK173=0,"",INDEX('Part types'!$T:$T,$AK173)&"") -> All vehicles | AF173: =IF($AK173=0,"",INDEX('Part types'!$U:$U,$AK173)&"") -> Liquid / flammable | AG173: =IF($AK173=0,"",INDEX('Part types'!$V:$V,$AK173)&"") -> Estimate: item-specific | AH173: =IF($AK173=0,"",INDEX('Part types'!$W:$W,$AK173)&"") -> Coolant Concentrate | AI173: =IF($AK173=0,"",INDEX('Part types'!$X:$X,$AK173)&"") | AJ173: =IF($AK173=0,"",INDEX('Part types'!$Y:$Y,$AK173)&"") | AK173: =IFERROR(MATCH($AD173,'Part types'!$E:$E,0),0) -> 167
... A187: SKU1185 | B187: Chemicals | C187: Anti-Seize Compound | D187: =C187&" "&INDEX('Part types'!$I:$I,$AK187) -> Anti-Seize Compound 100 g | E187: Universal | F187: Universal Fit | G187: =IF($AK187=0,"",INDEX('Part types'!$P:$P,$AK187)) -> 10 | H187: =IF($AK187=0,"",INDEX('Part types'!$Q:$Q,$AK187)) -> 8 | I187: =IF($AK187=0,"",INDEX('Part types'!$R:$R,$AK187)) -> 6 | J187: =IF($AK187=0,"",INDEX('Part types'!$S:$S,$AK187)) -> 0.1 | K187: الكيماويات | L187: معجون منع الالتصاق | M187: =L187&" "&INDEX('Part types'!$J:$J,$AK187) -> معجون منع الالتصاق 100 جم | N187: عام | O187: تركيب عام | P187: =G187 -> 10 | Q187: =H187 -> 8 | R187: =I187 -> 6 | S187: =J187 -> 0.1 | T187: 化学品 | U187: 防卡剂 | V187: =U187&" "&INDEX('Part types'!$K:$K,$AK187) -> 防卡剂 100克 | W187: 通用 | X187: 通用安装 | Y187: =G187 -> 10 | Z187: =H187 -> 8 | AA187: =I187 -> 6 | AB187: =J187 -> 0.1 | AC187: CHM | AD187: CHM-010 | AE187: =IF($AK187=0,"",INDEX('Part types'!$T:$T,$AK187)&"") -> All vehicles | AF187: =IF($AK187=0,"",INDEX('Part types'!$U:$U,$AK187)&"") -> Liquid / flammable | AG187: =IF($AK187=0,"",INDEX('Part types'!$V:$V,$AK187)&"") -> Estimate: size class XS | AH187: =IF($AK187=0,"",INDEX('Part types'!$W:$W,$AK187)&"") | AI187: =IF($AK187=0,"",INDEX('Part types'!$X:$X,$AK187)&"") | AJ187: =IF($AK187=0,"",INDEX('Part types'!$Y:$Y,$AK187)&"") | AK187: =IFERROR(MATCH($AD187,'Part types'!$E:$E,0),0) -> 181
A188: SKU1186 | B188: Chemicals | C188: Battery Terminal Protector | D188: =C188&" - "&E188 -> Battery Terminal Protector - Universal | E188: Universal | F188: Universal Fit | G188: =IF($AK188=0,"",INDEX('Part types'!$P:$P,$AK188)) -> 10 | H188: =IF($AK188=0,"",INDEX('Part types'!$Q:$Q,$AK188)) -> 8 | I188: =IF($AK188=0,"",INDEX('Part types'!$R:$R,$AK188)) -> 6 | J188: =IF($AK188=0,"",INDEX('Part types'!$S:$S,$AK188)) -> 0.1 | K188: الكيماويات | L188: حماية أقطاب البطارية | M188: =L188&" - "&N188 -> حماية أقطاب البطارية - عام | N188: عام | O188: تركيب عام | P188: =G188 -> 10 | Q188: =H188 -> 8 | R188: =I188 -> 6 | S188: =J188 -> 0.1 | T188: 化学品 | U188: 电瓶接线柱保护剂 | V188: =U188&" - "&W188 -> 电瓶接线柱保护剂 - 通用 | W188: 通用 | X188: 通用安装 | Y188: =G188 -> 10 | Z188: =H188 -> 8 | AA188: =I188 -> 6 | AB188: =J188 -> 0.1 | AC188: CHM | AD188: CHM-011 | AE188: =IF($AK188=0,"",INDEX('Part types'!$T:$T,$AK188)&"") -> All vehicles | AF188: =IF($AK188=0,"",INDEX('Part types'!$U:$U,$AK188)&"") -> Liquid / flammable | AG188: =IF($AK188=0,"",INDEX('Part types'!$V:$V,$AK188)&"") -> Estimate: size class XS | AH188: =IF($AK188=0,"",INDEX('Part types'!$W:$W,$AK188)&"") | AI188: =IF($AK188=0,"",INDEX('Part types'!$X:$X,$AK188)&"") | AJ188: =IF($AK188=0,"",INDEX('Part types'!$Y:$Y,$AK188)&"") | AK188: =IFERROR(MATCH($AD188,'Part types'!$E:$E,0),0) -> 182
A189: SKU1187 | B189: Chemicals | C189: Refrigerant | D189: =C189&" "&INDEX('Part types'!$I:$I,$AK189) -> Refrigerant R134a 500 g | E189: Universal | F189: Universal Fit | G189: =IF($AK189=0,"",INDEX('Part types'!$P:$P,$AK189)) -> 7 | H189: =IF($AK189=0,"",INDEX('Part types'!$Q:$Q,$AK189)) -> 7 | I189: =IF($AK189=0,"",INDEX('Part types'!$R:$R,$AK189)) -> 25 | J189: =IF($AK189=0,"",INDEX('Part types'!$S:$S,$AK189)) -> 0.6 | K189: الكيماويات | L189: غاز تكييف | M189: =L189&" "&INDEX('Part types'!$J:$J,$AK189) -> غاز تكييف R134a 500 جم | N189: عام | O189: تركيب عام | P189: =G189 -> 7 | Q189: =H189 -> 7 | R189: =I189 -> 25 | S189: =J189 -> 0.6 | T189: 化学品 | U189: 制冷剂 | V189: =U189&" "&INDEX('Part types'!$K:$K,$AK189) -> 制冷剂 R134a 500克 | W189: 通用 | X189: 通用安装 | Y189: =G189 -> 7 | Z189: =H189 -> 7 | AA189: =I189 -> 25 | AB189: =J189 -> 0.6 | AC189: CHM | AD189: CHM-012 | AE189: =IF($AK189=0,"",INDEX('Part types'!$T:$T,$AK189)&"") -> All vehicles | AF189: =IF($AK189=0,"",INDEX('Part types'!$U:$U,$AK189)&"") -> Liquid / flammable; Pressurised gas | AG189: =IF($AK189=0,"",INDEX('Part types'!$V:$V,$AK189)&"") -> Estimate: item-specific | AH189: =IF($AK189=0,"",INDEX('Part types'!$W:$W,$AK189)&"") -> Refrigerant R134a | AI189: =IF($AK189=0,"",INDEX('Part types'!$X:$X,$AK189)&"") | AJ189: =IF($AK189=0,"",INDEX('Part types'!$Y:$Y,$AK189)&"") | AK189: =IFERROR(MATCH($AD189,'Part types'!$E:$E,0),0) -> 183
A190: SKU1188 | B190: Chemicals | C190: Refrigerant | D190: =C190&" "&INDEX('Part types'!$I:$I,$AK190) -> Refrigerant R1234yf 500 g | E190: Universal | F190: Universal Fit | G190: =IF($AK190=0,"",INDEX('Part types'!$P:$P,$AK190)) -> 7 | H190: =IF($AK190=0,"",INDEX('Part types'!$Q:$Q,$AK190)) -> 7 | I190: =IF($AK190=0,"",INDEX('Part types'!$R:$R,$AK190)) -> 25 | J190: =IF($AK190=0,"",INDEX('Part types'!$S:$S,$AK190)) -> 0.6 | K190: الكيماويات | L190: غاز تكييف | M190: =L190&" "&INDEX('Part types'!$J:$J,$AK190) -> غاز تكييف R1234yf 500 جم | N190: عام | O190: تركيب عام | P190: =G190 -> 7 | Q190: =H190 -> 7 | R190: =I190 -> 25 | S190: =J190 -> 0.6 | T190: 化学品 | U190: 制冷剂 | V190: =U190&" "&INDEX('Part types'!$K:$K,$AK190) -> 制冷剂 R1234yf 500克 | W190: 通用 | X190: 通用安装 | Y190: =G190 -> 7 | Z190: =H190 -> 7 | AA190: =I190 -> 25 | AB190: =J190 -> 0.6 | AC190: CHM | AD190: CHM-013 | AE190: =IF($AK190=0,"",INDEX('Part types'!$T:$T,$AK190)&"") -> All vehicles | AF190: =IF($AK190=0,"",INDEX('Part types'!$U:$U,$AK190)&"") -> Liquid / flammable; Pressurised gas | AG190: =IF($AK190=0,"",INDEX('Part types'!$V:$V,$AK190)&"") -> Estimate: item-specific | AH190: =IF($AK190=0,"",INDEX('Part types'!$W:$W,$AK190)&"") -> Refrigerant R1234yf | AI190: =IF($AK190=0,"",INDEX('Part types'!$X:$X,$AK190)&"") | AJ190: =IF($AK190=0,"",INDEX('Part types'!$Y:$Y,$AK190)&"") | AK190: =IFERROR(MATCH($AD190,'Part types'!$E:$E,0),0) -> 184
A191: SKU1189 | B191: Chemicals | C191: Compressor Oil | D191: =C191&" "&INDEX('Part types'!$I:$I,$AK191) -> Compressor Oil PAG 250 ml | E191: Universal | F191: Universal Fit | G191: =IF($AK191=0,"",INDEX('Part types'!$P:$P,$AK191)) -> 6 | H191: =IF($AK191=0,"",INDEX('Part types'!$Q:$Q,$AK191)) -> 6 | I191: =IF($AK191=0,"",INDEX('Part types'!$R:$R,$AK191)) -> 16 | J191: =IF($AK191=0,"",INDEX('Part types'!$S:$S,$AK191)) -> 0.3 | K191: الكيماويات | L191: زيت كمبروسر التكييف | M191: =L191&" "&INDEX('Part types'!$J:$J,$AK191) -> زيت كمبروسر التكييف PAG 250 مل | N191: عام | O191: تركيب عام | P191: =G191 -> 6 | Q191: =H191 -> 6 | R191: =I191 -> 16 | S191: =J191 -> 0.3 | T191: 化学品 | U191: 空调压缩机油 | V191: =U191&" "&INDEX('Part types'!$K:$K,$AK191) -> 空调压缩机油 PAG 250毫升 | W191: 通用 | X191: 通用安装 | Y191: =G191 -> 6 | Z191: =H191 -> 6 | AA191: =I191 -> 16 | AB191: =J191 -> 0.3 | AC191: CHM | AD191: CHM-014 | AE191: =IF($AK191=0,"",INDEX('Part types'!$T:$T,$AK191)&"") -> All vehicles | AF191: =IF($AK191=0,"",INDEX('Part types'!$U:$U,$AK191)&"") -> Liquid / flammable | AG191: =IF($AK191=0,"",INDEX('Part types'!$V:$V,$AK191)&"") -> Estimate: item-specific | AH191: =IF($AK191=0,"",INDEX('Part types'!$W:$W,$AK191)&"") -> A/C Compressor Oil PAG | AI191: =IF($AK191=0,"",INDEX('Part types'!$X:$X,$AK191)&"") | AJ191: =IF($AK191=0,"",INDEX('Part types'!$Y:$Y,$AK191)&"") | AK191: =IFERROR(MATCH($AD191,'Part types'!$E:$E,0),0) -> 185
A192: SKU1190 | B192: Chemicals | C192: Tire Sealant | D192: =C192&" "&INDEX('Part types'!$I:$I,$AK192) -> Tire Sealant 450 ml | E192: Universal | F192: Universal Fit | G192: =IF($AK192=0,"",INDEX('Part types'!$P:$P,$AK192)) -> 7 | H192: =IF($AK192=0,"",INDEX('Part types'!$Q:$Q,$AK192)) -> 7 | I192: =IF($AK192=0,"",INDEX('Part types'!$R:$R,$AK192)) -> 22 | J192: =IF($AK192=0,"",INDEX('Part types'!$S:$S,$AK192)) -> 0.5 | K192: الكيماويات | L192: معجون إصلاح الإطارات | M192: =L192&" "&INDEX('Part types'!$J:$J,$AK192) -> معجون إصلاح الإطارات 450 مل | N192: عام | O192: تركيب عام | P192: =G192 -> 7 | Q192: =H192 -> 7 | R192: =I192 -> 22 | S192: =J192 -> 0.5 | T192: 化学品 | U192: 轮胎密封剂 | V192: =U192&" "&INDEX('Part types'!$K:$K,$AK192) -> 轮胎密封剂 450毫升 | W192: 通用 | X192: 通用安装 | Y192: =G192 -> 7 | Z192: =H192 -> 7 | AA192: =I192 -> 22 | AB192: =J192 -> 0.5 | AC192: CHM | AD192: CHM-015 | AE192: =IF($AK192=0,"",INDEX('Part types'!$T:$T,$AK192)&"") -> All vehicles | AF192: =IF($AK192=0,"",INDEX('Part types'!$U:$U,$AK192)&"") -> Liquid / flammable; Pressurised gas | AG192: =IF($AK192=0,"",INDEX('Part types'!$V:$V,$AK192)&"") -> Estimate: item-specific | AH192: =IF($AK192=0,"",INDEX('Part types'!$W:$W,$AK192)&"") | AI192: =IF($AK192=0,"",INDEX('Part types'!$X:$X,$AK192)&"") | AJ192: =IF($AK192=0,"",INDEX('Part types'!$Y:$Y,$AK192)&"") | AK192: =IFERROR(MATCH($AD192,'Part types'!$E:$E,0),0) -> 186
A193: SKU1191 | B193: Transmission | C193: Automatic Transmission Assembly | D193: =C193&" - "&E193 -> Automatic Transmission Assembly - Universal | E193: Universal | F193: Transmission | G193: =IF($AK193=0,"",INDEX('Part types'!$P:$P,$AK193)) -> 70 | H193: =IF($AK193=0,"",INDEX('Part types'!$Q:$Q,$AK193)) -> 50 | I193: =IF($AK193=0,"",INDEX('Part types'!$R:$R,$AK193)) -> 50 | J193: =IF($AK193=0,"",INDEX('Part types'!$S:$S,$AK193)) -> 70 | K193: ناقل الحركة | L193: ناقل حركة أوتوماتيك كامل | M193: =L193&" - "&N193 -> ناقل حركة أوتوماتيك كامل - عام | N193: عام | O193: ناقل الحركة | P193: =G193 -> 70 | Q193: =H193 -> 50 | R193: =I193 -> 50 | S193: =J193 -> 70 | T193: 变速箱 | U193: 自动变速箱总成 | V193: =U193&" - "&W193 -> 自动变速箱总成 - 通用 | W193: 通用 | X193: 变速箱 | Y193: =G193 -> 70 | Z193: =H193 -> 50 | AA193: =I193 -> 50 | AB193: =J193 -> 70 | AC193: TRN | AD193: TRN-001 | AE193: =IF($AK193=0,"",INDEX('Part types'!$T:$T,$AK193)&"") -> Combustion engine (petrol, diesel, hybrid, range extender) | AF193: =IF($AK193=0,"",INDEX('Part types'!$U:$U,$AK193)&"") -> Heavy (over 30 kg) | AG193: =IF($AK193=0,"",INDEX('Part types'!$V:$V,$AK193)&"") -> Estimate: item-specific | AH193: =IF($AK193=0,"",INDEX('Part types'!$W:$W,$AK193)&"") | AI193: =IF($AK193=0,"",INDEX('Part types'!$X:$X,$AK193)&"") | AJ193: =IF($AK193=0,"",INDEX('Part types'!$Y:$Y,$AK193)&"") | AK193: =IFERROR(MATCH($AD193,'Part types'!$E:$E,0),0) -> 187
A194: SKU1192 | B194: Transmission | C194: Manual Transmission Assembly | D194: =C194&" - "&E194 -> Manual Transmission Assembly - Universal | E194: Universal | F194: Transmission | G194: =IF($AK194=0,"",INDEX('Part types'!$P:$P,$AK194)) -> 60 | H194: =IF($AK194=0,"",INDEX('Part types'!$Q:$Q,$AK194)) -> 45 | I194: =IF($AK194=0,"",INDEX('Part types'!$R:$R,$AK194)) -> 45 | J194: =IF($AK194=0,"",INDEX('Part types'!$S:$S,$AK194)) -> 45 | K194: ناقل الحركة | L194: ناقل حركة عادي كامل | M194: =L194&" - "&N194 -> ناقل حركة عادي كامل - عام | N194: عام | O194: ناقل الحركة | P194: =G194 -> 60 | Q194: =H194 -> 45 | R194: =I194 -> 45 | S194: =J194 -> 45 | T194: 变速箱 | U194: 手动变速箱总成 | V194: =U194&" - "&W194 -> 手动变速箱总成 - 通用 | W194: 通用 | X194: 变速箱 | Y194: =G194 -> 60 | Z194: =H194 -> 45 | AA194: =I194 -> 45 | AB194: =J194 -> 45 | AC194: TRN | AD194: TRN-002 | AE194: =IF($AK194=0,"",INDEX('Part types'!$T:$T,$AK194)&"") -> Combustion engine (petrol, diesel, hybrid, range extender) | AF194: =IF($AK194=0,"",INDEX('Part types'!$U:$U,$AK194)&"") -> Heavy (over 30 kg) | AG194: =IF($AK194=0,"",INDEX('Part types'!$V:$V,$AK194)&"") -> Estimate: item-specific | AH194: =IF($AK194=0,"",INDEX('Part types'!$W:$W,$AK194)&"") | AI194: =IF($AK194=0,"",INDEX('Part types'!$X:$X,$AK194)&"") | AJ194: =IF($AK194=0,"",INDEX('Part types'!$Y:$Y,$AK194)&"") | AK194: =IFERROR(MATCH($AD194,'Part types'!$E:$E,0),0) -> 188
A195: SKU1193 | B195: Transmission | C195: Transmission Mount | D195: =C195&" - "&E195 -> Transmission Mount - Universal | E195: Universal | F195: Transmission | G195: =IF($AK195=0,"",INDEX('Part types'!$P:$P,$AK195)) -> 30 | H195: =IF($AK195=0,"",INDEX('Part types'!$Q:$Q,$AK195)) -> 20 | I195: =IF($AK195=0,"",INDEX('Part types'!$R:$R,$AK195)) -> 15 | J195: =IF($AK195=0,"",INDEX('Part types'!$S:$S,$AK195)) -> 1.8 | K195: ناقل الحركة | L195: قاعدة ناقل الحركة | M195: =L195&" - "&N195 -> قاعدة ناقل الحركة - عام | N195: عام | O195: ناقل الحركة | P195: =G195 -> 30 | Q195: =H195 -> 20 | R195: =I195 -> 15 | S195: =J195 -> 1.8 | T195: 变速箱 | U195: 变速箱脚垫 | V195: =U195&" - "&W195 -> 变速箱脚垫 - 通用 | W195: 通用 | X195: 变速箱 | Y195: =G195 -> 30 | Z195: =H195 -> 20 | AA195: =I195 -> 15 | AB195: =J195 -> 1.8 | AC195: TRN | AD195: TRN-003 | AE195: =IF($AK195=0,"",INDEX('Part types'!$T:$T,$AK195)&"") -> Combustion engine (petrol, diesel, hybrid, range extender) | AF195: =IF($AK195=0,"",INDEX('Part types'!$U:$U,$AK195)&"") | AG195: =IF($AK195=0,"",INDEX('Part types'!$V:$V,$AK195)&"") -> Estimate: size class M2 | AH195: =IF($AK195=0,"",INDEX('Part types'!$W:$W,$AK195)&"") | AI195: =IF($AK195=0,"",INDEX('Part types'!$X:$X,$AK195)&"") | AJ195: =IF($AK195=0,"",INDEX('Part types'!$Y:$Y,$AK195)&"") -> 悬置 | AK195: =IFERROR(MATCH($AD195,'Part types'!$E:$E,0),0) -> 189
A196: SKU1194 | B196: Transmission | C196: Transmission Oil Pan | D196: =C196&" - "&E196 -> Transmission Oil Pan - Universal | E196: Universal | F196: Transmission | G196: =IF($AK196=0,"",INDEX('Part types'!$P:$P,$AK196)) -> 40 | H196: =IF($AK196=0,"",INDEX('Part types'!$Q:$Q,$AK196)) -> 25 | I196: =IF($AK196=0,"",INDEX('Part types'!$R:$R,$AK196)) -> 15 | J196: =IF($AK196=0,"",INDEX('Part types'!$S:$S,$AK196)) -> 3 | K196: ناقل الحركة | L196: حوض زيت ناقل الحركة | M196: =L196&" - "&N196 -> حوض زيت ناقل الحركة - عام | N196: عام | O196: ناقل الحركة | P196: =G196 -> 40 | Q196: =H196 -> 25 | R196: =I196 -> 15 | S196: =J196 -> 3 | T196: 变速箱 | U196: 变速箱油底壳 | V196: =U196&" - "&W196 -> 变速箱油底壳 - 通用 | W196: 通用 | X196: 变速箱 | Y196: =G196 -> 40 | Z196: =H196 -> 25 | AA196: =I196 -> 15 | AB196: =J196 -> 3 | AC196: TRN | AD196: TRN-004 | AE196: =IF($AK196=0,"",INDEX('Part types'!$T:$T,$AK196)&"") -> Combustion engine (petrol, diesel, hybrid, range extender) | AF196: =IF($AK196=0,"",INDEX('Part types'!$U:$U,$AK196)&"") | AG196: =IF($AK196=0,"",INDEX('Part types'!$V:$V,$AK196)&"") -> Estimate: size class L | AH196: =IF($AK196=0,"",INDEX('Part types'!$W:$W,$AK196)&"") | AI196: =IF($AK196=0,"",INDEX('Part types'!$X:$X,$AK196)&"") | AJ196: =IF($AK196=0,"",INDEX('Part types'!$Y:$Y,$AK196)&"") | AK196: =IFERROR(MATCH($AD196,'Part types'!$E:$E,0),0) -> 190
A197: SKU1195 | B197: Transmission | C197: Transmission Pan Gasket | D197: =C197&" - "&E197 -> Transmission Pan Gasket - Universal | E197: Universal | F197: Transmission | G197: =IF($AK197=0,"",INDEX('Part types'!$P:$P,$AK197)) -> 15 | H197: =IF($AK197=0,"",INDEX('Part types'!$Q:$Q,$AK197)) -> 10 | I197: =IF($AK197=0,"",INDEX('Part types'!$R:$R,$AK197)) -> 8 | J197: =IF($AK197=0,"",INDEX('Part types'!$S:$S,$AK197)) -> 0.3 | K197: ناقل الحركة | L197: جوان حوض ناقل الحركة | M197: =L197&" - "&N197 -> جوان حوض ناقل الحركة - عام | N197: عام | O197: ناقل الحركة | P197: =G197 -> 15 | Q197: =H197 -> 10 | R197: =I197 -> 8 | S197: =J197 -> 0.3 | T197: 变速箱 | U197: 变速箱油底壳垫 | V197: =U197&" - "&W197 -> 变速箱油底壳垫 - 通用 | W197: 通用 | X197: 变速箱 | Y197: =G197 -> 15 | Z197: =H197 -> 10 | AA197: =I197 -> 8 | AB197: =J197 -> 0.3 | AC197: TRN | AD197: TRN-005 | AE197: =IF($AK197=0,"",INDEX('Part types'!$T:$T,$AK197)&"") -> Combustion engine (petrol, diesel, hybrid, range extender) | AF197: =IF($AK197=0,"",INDEX('Part types'!$U:$U,$AK197)&"") | AG197: =IF($AK197=0,"",INDEX('Part types'!$V:$V,$AK197)&"") -> Estimate: size class S | AH197: =IF($AK197=0,"",INDEX('Part types'!$W:$W,$AK197)&"") | AI197: =IF($AK197=0,"",INDEX('Part types'!$X:$X,$AK197)&"") | AJ197: =IF($AK197=0,"",INDEX('Part types'!$Y:$Y,$AK197)&"") | AK197: =IFERROR(MATCH($AD197,'Part types'!$E:$E,0),0) -> 191
A198: SKU1196 | B198: Transmission | C198: Transmission Valve Body | D198: =C198&" - "&E198 -> Transmission Valve Body - Universal | E198: Universal | F198: Transmission | G198: =IF($AK198=0,"",INDEX('Part types'!$P:$P,$AK198)) -> 35 | H198: =IF($AK198=0,"",INDEX('Part types'!$Q:$Q,$AK198)) -> 25 | I198: =IF($AK198=0,"",INDEX('Part types'!$R:$R,$AK198)) -> 12 | J198: =IF($AK198=0,"",INDEX('Part types'!$S:$S,$AK198)) -> 6 | K198: ناقل الحركة | L198: وحدة الصمامات | M198: =L198&" - "&N198 -> وحدة الصمامات - عام | N198: عام | O198: ناقل الحركة | P198: =G198 -> 35 | Q198: =H198 -> 25 | R198: =I198 -> 12 | S198: =J198 -> 6 | T198: 变速箱 | U198: 变速箱阀体 | V198: =U198&" - "&W198 -> 变速箱阀体 - 通用 | W198: 通用 | X198: 变速箱 | Y198: =G198 -> 35 | Z198: =H198 -> 25 | AA198: =I198 -> 12 | AB198: =J198 -> 6 | AC198: TRN | AD198: TRN-006 | AE198: =IF($AK198=0,"",INDEX('Part types'!$T:$T,$AK198)&"") -> Combustion engine (petrol, diesel, hybrid, range extender) | AF198: =IF($AK198=0,"",INDEX('Part types'!$U:$U,$AK198)&"") | AG198: =IF($AK198=0,"",INDEX('Part types'!$V:$V,$AK198)&"") -> Estimate: item-specific | AH198: =IF($AK198=0,"",INDEX('Part types'!$W:$W,$AK198)&"") | AI198: =IF($AK198=0,"",INDEX('Part types'!$X:$X,$AK198)&"") -> فالف بودي | AJ198: =IF($AK198=0,"",INDEX('Part types'!$Y:$Y,$AK198)&"") | AK198: =IFERROR(MATCH($AD198,'Part types'!$E:$E,0),0) -> 192
A199: SKU1197 | B199: Transmission | C199: Transmission Shift Solenoid | D199: =C199&" - "&E199 -> Transmission Shift Solenoid - Universal | E199: Universal | F199: Transmission | G199: =IF($AK199=0,"",INDEX('Part types'!$P:$P,$AK199)) -> 10 | H199: =IF($AK199=0,"",INDEX('Part types'!$Q:$Q,$AK199)) -> 8 | I199: =IF($AK199=0,"",INDEX('Part types'!$R:$R,$AK199)) -> 6 | J199: =IF($AK199=0,"",INDEX('Part types'!$S:$S,$AK199)) -> 0.1 | K199: ناقل الحركة | L199: سولينويد تغيير السرعات | M199: =L199&" - "&N199 -> سولينويد تغيير السرعات - عام | N199: عام | O199: ناقل الحركة | P199: =G199 -> 10 | Q199: =H199 -> 8 | R199: =I199 -> 6 | S199: =J199 -> 0.1 | T199: 变速箱 | U199: 变速箱换挡电磁阀 | V199: =U199&" - "&W199 -> 变速箱换挡电磁阀 - 通用 | W199: 通用 | X199: 变速箱 | Y199: =G199 -> 10 | Z199: =H199 -> 8 | AA199: =I199 -> 6 | AB199: =J199 -> 0.1 | AC199: TRN | AD199: TRN-007 | AE199: =IF($AK199=0,"",INDEX('Part types'!$T:$T,$AK199)&"") -> Combustion engine (petrol, diesel, hybrid, range extender) | AF199: =IF($AK199=0,"",INDEX('Part types'!$U:$U,$AK199)&"") | AG199: =IF($AK199=0,"",INDEX('Part types'!$V:$V,$AK199)&"") -> Estimate: size class XS | AH199: =IF($AK199=0,"",INDEX('Part types'!$W:$W,$AK199)&"") | AI199: =IF($AK199=0,"",INDEX('Part types'!$X:$X,$AK199)&"") | AJ199: =IF($AK199=0,"",INDEX('Part types'!$Y:$Y,$AK199)&"") | AK199: =IFERROR(MATCH($AD199,'Part types'!$E:$E,0),0) -> 193
A200: SKU1198 | B200: Transmission | C200: Mechatronic Unit | D200: =C200&" - "&E200 -> Mechatronic Unit - Universal | E200: Universal | F200: Transmission | G200: =IF($AK200=0,"",INDEX('Part types'!$P:$P,$AK200)) -> 30 | H200: =IF($AK200=0,"",INDEX('Part types'!$Q:$Q,$AK200)) -> 20 | I200: =IF($AK200=0,"",INDEX('Part types'!$R:$R,$AK200)) -> 15 | J200: =IF($AK200=0,"",INDEX('Part types'!$S:$S,$AK200)) -> 1.8 | K200: ناقل الحركة | L200: وحدة الميكاترونيك | M200: =L200&" - "&N200 -> وحدة الميكاترونيك - عام | N200: عام | O200: ناقل الحركة | P200: =G200 -> 30 | Q200: =H200 -> 20 | R200: =I200 -> 15 | S200: =J200 -> 1.8 | T200: 变速箱 | U200: 机电单元 | V200: =U200&" - "&W200 -> 机电单元 - 通用 | W200: 通用 | X200: 变速箱 | Y200: =G200 -> 30 | Z200: =H200 -> 20 | AA200: =I200 -> 15 | AB200: =J200 -> 1.8 | AC200: TRN | AD200: TRN-008 | AE200: =IF($AK200=0,"",INDEX('Part types'!$T:$T,$AK200)&"") -> Combustion engine (petrol, diesel, hybrid, range extender) | AF200: =IF($AK200=0,"",INDEX('Part types'!$U:$U,$AK200)&"") | AG200: =IF($AK200=0,"",INDEX('Part types'!$V:$V,$AK200)&"") -> Estimate: size class M2 | AH200: =IF($AK200=0,"",INDEX('Part types'!$W:$W,$AK200)&"") -> DCT | AI200: =IF($AK200=0,"",INDEX('Part types'!$X:$X,$AK200)&"") -> DCT | AJ200: =IF($AK200=0,"",INDEX('Part types'!$Y:$Y,$AK200)&"") -> 双离合变速箱 | AK200: =IFERROR(MATCH($AD200,'Part types'!$E:$E,0),0) -> 194
...

Sheet Part types
A1: Main Category Code | B1: Main Category (English) | C1: Main Category (Arabic) | D1: Main Category (Chinese) | E1: Part Code | F1: Sub Category (English) | G1: Sub Category (Arabic) | H1: Sub Category (Chinese) | I1: Variant (English) | J1: Variant (Arabic) | K1: Variant (Chinese) | L1: Allowed Positions | M1: Placement (English) | N1: Placement (Arabic) | O1: Placement (Chinese) | P1: Length (cm) | Q1: Width (cm) | R1: Height (cm) | S1: Weight (kg) | T1: Applies To | U1: Special Shipping | V1: Size Basis | W1: Search Keywords (English) | X1: Search Keywords (Arabic) | Y1: Search Keywords (Chinese)
A2: ENG | B2: Engine | C2: المحرك | D2: 发动机 | E2: ENG-001 | F2: Engine Assembly | G2: محرك كامل | H2: 发动机总成 | L2: Universal | M2: Engine Bay | N2: حجرة المحرك | O2: 发动机舱 | P2: 110 | Q2: 75 | R2: 75 | S2: 150 | T2: Combustion engine (petrol, diesel, hybrid, range extender) | U2: Heavy (over 30 kg) | V2: Estimate: item-specific | W2: Complete
A3: ENG | B3: Engine | C3: المحرك | D3: 发动机 | E3: ENG-002 | F3: Short Block | G3: هيكل المحرك | H3: 发动机短缸体总成 | L3: Universal | M3: Engine Bay | N3: حجرة المحرك | O3: 发动机舱 | P3: 80 | Q3: 60 | R3: 60 | S3: 80 | T3: Combustion engine (petrol, diesel, hybrid, range extender) | U3: Heavy (over 30 kg) | V3: Estimate: item-specific | X3: شورت بلوك
A4: ENG | B4: Engine | C4: المحرك | D4: 发动机 | E4: ENG-003 | F4: Cylinder Block | G4: كتلة الأسطوانات | H4: 气缸体 | L4: Universal | M4: Engine Block | N4: كتلة المحرك | O4: 缸体 | P4: 60 | Q4: 45 | R4: 40 | S4: 35 | T4: Combustion engine (petrol, diesel, hybrid, range extender) | U4: Heavy (over 30 kg) | V4: Estimate: item-specific
A5: ENG | B5: Engine | C5: المحرك | D5: 发动机 | E5: ENG-004 | F5: Cylinder Head | G5: رأس الأسطوانات | H5: 气缸盖 | L5: Universal | M5: Cylinder Head | N5: رأس الأسطوانات | O5: 气缸盖 | P5: 60 | Q5: 30 | R5: 25 | S5: 18 | T5: Combustion engine (petrol, diesel, hybrid, range extender) | V5: Estimate: item-specific
A6: ENG | B6: Engine | C6: المحرك | D6: 发动机 | E6: ENG-005 | F6: Cylinder Head Gasket | G6: جوان رأس الأسطوانات | H6: 气缸垫 | L6: Universal | M6: Cylinder Head | N6: رأس الأسطوانات | O6: 气缸盖 | P6: 50 | Q6: 30 | R6: 3 | S6: 0.4 | T6: Combustion engine (petrol, diesel, hybrid, range extender) | V6: Estimate: item-specific
A7: ENG | B7: Engine | C7: المحرك | D7: 发动机 | E7: ENG-006 | F7: Head Bolt Set | G7: طقم براغي رأس الأسطوانات | H7: 缸盖螺栓套装 | L7: Universal | M7: Cylinder Head | N7: رأس الأسطوانات | O7: 气缸盖 | P7: 25 | Q7: 15 | R7: 10 | S7: 0.9 | T7: Combustion engine (petrol, diesel, hybrid, range extender) | V7: Estimate: size class M | W7: Cylinder Head Bolt Set
A8: ENG | B8: Engine | C8: المحرك | D8: 发动机 | E8: ENG-007 | F8: Valve Cover | G8: غطاء الصمامات | H8: 气门室盖 | L8: Universal | M8: Engine Top | N8: أعلى المحرك | O8: 发动机顶部 | P8: 40 | Q8: 25 | R8: 15 | S8: 3 | T8: Combustion engine (petrol, diesel, hybrid, range extender) | V8: Estimate: size class L
A9: ENG | B9: Engine | C9: المحرك | D9: 发动机 | E9: ENG-008 | F9: Valve Cover Gasket | G9: جوان غطاء الصمامات | H9: 气门室盖垫 | L9: Universal | M9: Engine Top | N9: أعلى المحرك | O9: 发动机顶部 | P9: 15 | Q9: 10 | R9: 8 | S9: 0.3 | T9: Combustion engine (petrol, diesel, hybrid, range extender) | V9: Estimate: size class S
A10: ENG | B10: Engine | C10: المحرك | D10: 发动机 | E10: ENG-009 | F10: Piston | G10: مكبس | H10: 活塞 | L10: Universal | M10: Engine Internal | N10: داخل المحرك | O10: 发动机内部 | P10: 10 | Q10: 8 | R10: 6 | S10: 0.1 | T10: Combustion engine (petrol, diesel, hybrid, range extender) | V10: Estimate: size class XS | X10: بستم
A11: ENG | B11: Engine | C11: المحرك | D11: 发动机 | E11: ENG-010 | F11: Piston Ring Set | G11: طقم شنابر المكبس | H11: 活塞环套装 | L11: Universal | M11: Engine Internal | N11: داخل المحرك | O11: 发动机内部 | P11: 15 | Q11: 10 | R11: 8 | S11: 0.3 | T11: Combustion engine (petrol, diesel, hybrid, range extender) | V11: Estimate: size class S
A12: ENG | B12: Engine | C12: المحرك | D12: 发动机 | E12: ENG-011 | F12: Piston Pin | G12: مسمار المكبس | H12: 活塞销 | L12: Universal | M12: Engine Internal | N12: داخل المحرك | O12: 发动机内部 | P12: 10 | Q12: 8 | R12: 6 | S12: 0.1 | T12: Combustion engine (petrol, diesel, hybrid, range extender) | V12: Estimate: size class XS
A13: ENG | B13: Engine | C13: المحرك | D13: 发动机 | E13: ENG-012 | F13: Connecting Rod | G13: ذراع التوصيل | H13: 连杆 | L13: Universal | M13: Engine Internal | N13: داخل المحرك | O13: 发动机内部 | P13: 15 | Q13: 10 | R13: 8 | S13: 0.3 | T13: Combustion engine (petrol, diesel, hybrid, range extender) | V13: Estimate: size class S | X13: البيل
A14: ENG | B14: Engine | C14: المحرك | D14: 发动机 | E14: ENG-013 | F14: Rod Bearing Set | G14: طقم كراسي ذراع التوصيل | H14: 连杆轴瓦套装 | L14: Universal | M14: Engine Internal | N14: داخل المحرك | O14: 发动机内部 | P14: 15 | Q14: 10 | R14: 8 | S14: 0.3 | T14: Combustion engine (petrol, diesel, hybrid, range extender) | V14: Estimate: size class S | W14: Connecting Rod Bearing Set
